[2025-01-30T06:11:18.408+0000] {local_task_job_runner.py:123} INFO - ::group::Pre task execution logs
[2025-01-30T06:11:18.427+0000] {taskinstance.py:2613} INFO - Dependencies all met for dep_context=non-requeueable deps ti=<TaskInstance: prepare_churn_dataset.load manual__2025-01-30T06:11:09.552302+00:00 [queued]>
[2025-01-30T06:11:18.435+0000] {taskinstance.py:2613} INFO - Dependencies all met for dep_context=requeueable deps ti=<TaskInstance: prepare_churn_dataset.load manual__2025-01-30T06:11:09.552302+00:00 [queued]>
[2025-01-30T06:11:18.436+0000] {taskinstance.py:2866} INFO - Starting attempt 1 of 1
[2025-01-30T06:11:18.447+0000] {taskinstance.py:2889} INFO - Executing <Task(_PythonDecoratedOperator): load> on 2025-01-30 06:11:09.552302+00:00
[2025-01-30T06:11:18.455+0000] {standard_task_runner.py:72} INFO - Started process 202 to run task
[2025-01-30T06:11:18.458+0000] {standard_task_runner.py:104} INFO - Running: ['***', 'tasks', 'run', 'prepare_churn_dataset', 'load', 'manual__2025-01-30T06:11:09.552302+00:00', '--job-id', '43', '--raw', '--subdir', 'DAGS_FOLDER/churn.py', '--cfg-path', '/tmp/tmpyb9xushw']
[2025-01-30T06:11:18.460+0000] {standard_task_runner.py:105} INFO - Job 43: Subtask load
[2025-01-30T06:11:18.508+0000] {task_command.py:467} INFO - Running <TaskInstance: prepare_churn_dataset.load manual__2025-01-30T06:11:09.552302+00:00 [running]> on host 0be31ceb717f
[2025-01-30T06:11:18.780+0000] {taskinstance.py:3132} INFO - Exporting env vars: AIRFLOW_CTX_DAG_OWNER='***' AIRFLOW_CTX_DAG_ID='prepare_churn_dataset' AIRFLOW_CTX_TASK_ID='load' AIRFLOW_CTX_EXECUTION_DATE='2025-01-30T06:11:09.552302+00:00' AIRFLOW_CTX_TRY_NUMBER='1' AIRFLOW_CTX_DAG_RUN_ID='manual__2025-01-30T06:11:09.552302+00:00'
[2025-01-30T06:11:18.783+0000] {logging_mixin.py:190} INFO - Task instance is in running state
[2025-01-30T06:11:18.784+0000] {logging_mixin.py:190} INFO -  Previous state of the Task instance: queued
[2025-01-30T06:11:18.784+0000] {logging_mixin.py:190} INFO - Current task name:load state:running start_date:2025-01-30 06:11:18.428508+00:00
[2025-01-30T06:11:18.785+0000] {logging_mixin.py:190} INFO - Dag name:prepare_churn_dataset and current dag run status:running
[2025-01-30T06:11:18.785+0000] {taskinstance.py:731} INFO - ::endgroup::
[2025-01-30T06:11:18.786+0000] {churn.py:103} INFO - Загрузка данных в целевую таблицу.
[2025-01-30T06:11:18.796+0000] {base.py:84} INFO - Retrieving connection 'destination_db'
[2025-01-30T06:11:18.797+0000] {sql.py:186} WARNING - This setter is for backward compatibility and should not be used.
Since the introduction of connection property, the providers listed below breaks due to assigning value to self.connection in their __init__ method.
* apache-***-providers-mysql<5.7.1
* apache-***-providers-elasticsearch<5.5.1
* apache-***-providers-postgres<5.13.0
[2025-01-30T06:11:18.939+0000] {taskinstance.py:3311} ERROR - Task failed with exception
Traceback (most recent call last):
  File "/home/airflow/.local/lib/python3.10/site-packages/airflow/models/taskinstance.py", line 767, in _execute_task
    result = _execute_callable(context=context, **execute_callable_kwargs)
  File "/home/airflow/.local/lib/python3.10/site-packages/airflow/models/taskinstance.py", line 733, in _execute_callable
    return ExecutionCallableRunner(
  File "/home/airflow/.local/lib/python3.10/site-packages/airflow/utils/operator_helpers.py", line 252, in run
    return self.func(*args, **kwargs)
  File "/home/airflow/.local/lib/python3.10/site-packages/airflow/models/baseoperator.py", line 422, in wrapper
    return func(self, *args, **kwargs)
  File "/home/airflow/.local/lib/python3.10/site-packages/airflow/decorators/base.py", line 266, in execute
    return_value = super().execute(context)
  File "/home/airflow/.local/lib/python3.10/site-packages/airflow/models/baseoperator.py", line 422, in wrapper
    return func(self, *args, **kwargs)
  File "/home/airflow/.local/lib/python3.10/site-packages/airflow/operators/python.py", line 238, in execute
    return_value = self.execute_callable()
  File "/home/airflow/.local/lib/python3.10/site-packages/airflow/operators/python.py", line 256, in execute_callable
    return runner.run(*self.op_args, **self.op_kwargs)
  File "/home/airflow/.local/lib/python3.10/site-packages/airflow/utils/operator_helpers.py", line 252, in run
    return self.func(*args, **kwargs)
  File "/opt/airflow/dags/churn.py", line 105, in load
    hook.insert_rows(
  File "/home/airflow/.local/lib/python3.10/site-packages/airflow/providers/common/sql/hooks/sql.py", line 644, in insert_rows
    sql = self._generate_insert_sql(table, values, target_fields, replace, **kwargs)
  File "/home/airflow/.local/lib/python3.10/site-packages/airflow/providers/postgres/hooks/postgres.py", line 302, in _generate_insert_sql
    sql = f"INSERT INTO {table} {target_fields_fragment} VALUES ({','.join(placeholders)})"
TypeError: sequence item 0: expected str instance, cached_property found
[2025-01-30T06:11:18.950+0000] {logging_mixin.py:190} INFO - Task instance in failure state
[2025-01-30T06:11:18.951+0000] {logging_mixin.py:190} INFO - Task start:2025-01-30 06:11:18.428508+00:00 end:2025-01-30 06:11:18.950376+00:00 duration:0.521868
[2025-01-30T06:11:18.952+0000] {logging_mixin.py:190} INFO - Task:<Task(_PythonDecoratedOperator): load> dag:<DAG: prepare_churn_dataset> dagrun:<DagRun prepare_churn_dataset @ 2025-01-30 06:11:09.552302+00:00: manual__2025-01-30T06:11:09.552302+00:00, state:running, queued_at: 2025-01-30 06:11:09.574344+00:00. externally triggered: True>
[2025-01-30T06:11:18.952+0000] {logging_mixin.py:190} INFO - Failure caused by sequence item 0: expected str instance, cached_property found
[2025-01-30T06:11:18.953+0000] {taskinstance.py:1225} INFO - Marking task as FAILED. dag_id=prepare_churn_dataset, task_id=load, run_id=manual__2025-01-30T06:11:09.552302+00:00, execution_date=20250130T061109, start_date=20250130T061118, end_date=20250130T061118
[2025-01-30T06:11:18.963+0000] {taskinstance.py:340} INFO - ::group::Post task execution logs
[2025-01-30T06:11:18.964+0000] {standard_task_runner.py:124} ERROR - Failed to execute job 43 for task load (sequence item 0: expected str instance, cached_property found; 202)
Traceback (most recent call last):
  File "/home/airflow/.local/lib/python3.10/site-packages/airflow/task/task_runner/standard_task_runner.py", line 117, in _start_by_fork
    ret = args.func(args, dag=self.dag)
  File "/home/airflow/.local/lib/python3.10/site-packages/airflow/cli/cli_config.py", line 49, in command
    return func(*args, **kwargs)
  File "/home/airflow/.local/lib/python3.10/site-packages/airflow/utils/cli.py", line 116, in wrapper
    return f(*args, **kwargs)
  File "/home/airflow/.local/lib/python3.10/site-packages/airflow/cli/commands/task_command.py", line 483, in task_run
    task_return_code = _run_task_by_selected_method(args, _dag, ti)
  File "/home/airflow/.local/lib/python3.10/site-packages/airflow/cli/commands/task_command.py", line 256, in _run_task_by_selected_method
    return _run_raw_task(args, ti)
  File "/home/airflow/.local/lib/python3.10/site-packages/airflow/cli/commands/task_command.py", line 341, in _run_raw_task
    return ti._run_raw_task(
  File "/home/airflow/.local/lib/python3.10/site-packages/airflow/utils/session.py", line 97, in wrapper
    return func(*args, session=session, **kwargs)
  File "/home/airflow/.local/lib/python3.10/site-packages/airflow/models/taskinstance.py", line 3005, in _run_raw_task
    return _run_raw_task(
  File "/home/airflow/.local/lib/python3.10/site-packages/airflow/models/taskinstance.py", line 273, in _run_raw_task
    TaskInstance._execute_task_with_callbacks(
  File "/home/airflow/.local/lib/python3.10/site-packages/airflow/models/taskinstance.py", line 3159, in _execute_task_with_callbacks
    result = self._execute_task(context, task_orig)
  File "/home/airflow/.local/lib/python3.10/site-packages/airflow/models/taskinstance.py", line 3183, in _execute_task
    return _execute_task(self, context, task_orig)
  File "/home/airflow/.local/lib/python3.10/site-packages/airflow/models/taskinstance.py", line 767, in _execute_task
    result = _execute_callable(context=context, **execute_callable_kwargs)
  File "/home/airflow/.local/lib/python3.10/site-packages/airflow/models/taskinstance.py", line 733, in _execute_callable
    return ExecutionCallableRunner(
  File "/home/airflow/.local/lib/python3.10/site-packages/airflow/utils/operator_helpers.py", line 252, in run
    return self.func(*args, **kwargs)
  File "/home/airflow/.local/lib/python3.10/site-packages/airflow/models/baseoperator.py", line 422, in wrapper
    return func(self, *args, **kwargs)
  File "/home/airflow/.local/lib/python3.10/site-packages/airflow/decorators/base.py", line 266, in execute
    return_value = super().execute(context)
  File "/home/airflow/.local/lib/python3.10/site-packages/airflow/models/baseoperator.py", line 422, in wrapper
    return func(self, *args, **kwargs)
  File "/home/airflow/.local/lib/python3.10/site-packages/airflow/operators/python.py", line 238, in execute
    return_value = self.execute_callable()
  File "/home/airflow/.local/lib/python3.10/site-packages/airflow/operators/python.py", line 256, in execute_callable
    return runner.run(*self.op_args, **self.op_kwargs)
  File "/home/airflow/.local/lib/python3.10/site-packages/airflow/utils/operator_helpers.py", line 252, in run
    return self.func(*args, **kwargs)
  File "/opt/airflow/dags/churn.py", line 105, in load
    hook.insert_rows(
  File "/home/airflow/.local/lib/python3.10/site-packages/airflow/providers/common/sql/hooks/sql.py", line 644, in insert_rows
    sql = self._generate_insert_sql(table, values, target_fields, replace, **kwargs)
  File "/home/airflow/.local/lib/python3.10/site-packages/airflow/providers/postgres/hooks/postgres.py", line 302, in _generate_insert_sql
    sql = f"INSERT INTO {table} {target_fields_fragment} VALUES ({','.join(placeholders)})"
TypeError: sequence item 0: expected str instance, cached_property found
[2025-01-30T06:11:18.997+0000] {local_task_job_runner.py:266} INFO - Task exited with return code 1
[2025-01-30T06:11:19.015+0000] {taskinstance.py:3895} INFO - 0 downstream tasks scheduled from follow-on schedule check
[2025-01-30T06:11:19.017+0000] {local_task_job_runner.py:245} INFO - ::endgroup::
