[2025-01-13T12:27:38.707+0000] {taskinstance.py:1159} INFO - Dependencies all met for dep_context=non-requeueable deps ti=<TaskInstance: prepare_flats_dataset.extract manual__2025-01-13T12:27:36.401754+00:00 [queued]>
[2025-01-13T12:27:38.714+0000] {taskinstance.py:1159} INFO - Dependencies all met for dep_context=requeueable deps ti=<TaskInstance: prepare_flats_dataset.extract manual__2025-01-13T12:27:36.401754+00:00 [queued]>
[2025-01-13T12:27:38.714+0000] {taskinstance.py:1361} INFO - Starting attempt 1 of 1
[2025-01-13T12:27:38.727+0000] {taskinstance.py:1382} INFO - Executing <Task(_PythonDecoratedOperator): extract> on 2025-01-13 12:27:36.401754+00:00
[2025-01-13T12:27:38.735+0000] {standard_task_runner.py:57} INFO - Started process 112 to run task
[2025-01-13T12:27:38.741+0000] {standard_task_runner.py:84} INFO - Running: ['***', 'tasks', 'run', 'prepare_flats_dataset', 'extract', 'manual__2025-01-13T12:27:36.401754+00:00', '--job-id', '95', '--raw', '--subdir', 'DAGS_FOLDER/charn2.py', '--cfg-path', '/tmp/tmpxnlni3if']
[2025-01-13T12:27:38.742+0000] {standard_task_runner.py:85} INFO - Job 95: Subtask extract
[2025-01-13T12:27:38.812+0000] {task_command.py:416} INFO - Running <TaskInstance: prepare_flats_dataset.extract manual__2025-01-13T12:27:36.401754+00:00 [running]> on host 687660880ddc
[2025-01-13T12:27:38.894+0000] {taskinstance.py:1662} INFO - Exporting env vars: AIRFLOW_CTX_DAG_OWNER='***' AIRFLOW_CTX_DAG_ID='prepare_flats_dataset' AIRFLOW_CTX_TASK_ID='extract' AIRFLOW_CTX_EXECUTION_DATE='2025-01-13T12:27:36.401754+00:00' AIRFLOW_CTX_TRY_NUMBER='1' AIRFLOW_CTX_DAG_RUN_ID='manual__2025-01-13T12:27:36.401754+00:00'
[2025-01-13T12:27:38.897+0000] {base.py:73} INFO - Using connection ID 'source_db' for task execution.
[2025-01-13T12:27:39.060+0000] {warnings.py:109} WARNING - /opt/***/dags/charn2.py:67: UserWarning: pandas only supports SQLAlchemy connectable (engine/connection) or database string URI or sqlite3 DBAPI2 connection. Other DBAPI2 objects are not tested. Please consider using SQLAlchemy.
  data = pd.read_sql(sql, conn)

[2025-01-13T12:27:39.147+0000] {taskinstance.py:1937} ERROR - Task failed with exception
Traceback (most recent call last):
  File "/home/airflow/.local/lib/python3.10/site-packages/pandas/io/sql.py", line 2262, in execute
    cur.execute(sql, *args)
psycopg2.errors.UndefinedTable: relation "flats" does not exist
LINE 6:         FROM flats AS f
                     ^


The above exception was the direct cause of the following exception:

Traceback (most recent call last):
  File "/home/airflow/.local/lib/python3.10/site-packages/airflow/decorators/base.py", line 221, in execute
    return_value = super().execute(context)
  File "/home/airflow/.local/lib/python3.10/site-packages/airflow/operators/python.py", line 192, in execute
    return_value = self.execute_callable()
  File "/home/airflow/.local/lib/python3.10/site-packages/airflow/operators/python.py", line 209, in execute_callable
    return self.python_callable(*self.op_args, **self.op_kwargs)
  File "/opt/airflow/dags/charn2.py", line 67, in extract
    data = pd.read_sql(sql, conn)
  File "/home/airflow/.local/lib/python3.10/site-packages/pandas/io/sql.py", line 654, in read_sql
    return pandas_sql.read_query(
  File "/home/airflow/.local/lib/python3.10/site-packages/pandas/io/sql.py", line 2326, in read_query
    cursor = self.execute(sql, params)
  File "/home/airflow/.local/lib/python3.10/site-packages/pandas/io/sql.py", line 2274, in execute
    raise ex from exc
pandas.errors.DatabaseError: Execution failed on sql '
        SELECT 
            f.flat_id, f.floor, f.is_apartment, f.kitchen_area, f.living_area, f.rooms, f.studio, f.total_area, 
            f.building_id, f.build_year, f.building_type_int, f.latitude, f.longitude, f.ceiling_height, 
            f.flats_count, f.floors_total, f.has_elevator, f.price
        FROM flats AS f
        ': relation "flats" does not exist
LINE 6:         FROM flats AS f
                     ^

[2025-01-13T12:27:39.158+0000] {taskinstance.py:1400} INFO - Marking task as FAILED. dag_id=prepare_flats_dataset, task_id=extract, execution_date=20250113T122736, start_date=20250113T122738, end_date=20250113T122739
[2025-01-13T12:27:39.173+0000] {standard_task_runner.py:104} ERROR - Failed to execute job 95 for task extract (Execution failed on sql '
        SELECT 
            f.flat_id, f.floor, f.is_apartment, f.kitchen_area, f.living_area, f.rooms, f.studio, f.total_area, 
            f.building_id, f.build_year, f.building_type_int, f.latitude, f.longitude, f.ceiling_height, 
            f.flats_count, f.floors_total, f.has_elevator, f.price
        FROM flats AS f
        ': relation "flats" does not exist
LINE 6:         FROM flats AS f
                     ^
; 112)
[2025-01-13T12:27:39.194+0000] {local_task_job_runner.py:228} INFO - Task exited with return code 1
[2025-01-13T12:27:39.215+0000] {taskinstance.py:2778} INFO - 0 downstream tasks scheduled from follow-on schedule check
