[2025-01-30T11:58:09.693+0000] {local_task_job_runner.py:123} INFO - ::group::Pre task execution logs
[2025-01-30T11:58:09.709+0000] {taskinstance.py:2613} INFO - Dependencies all met for dep_context=non-requeueable deps ti=<TaskInstance: clean_churn_dataset.extract manual__2025-01-30T11:58:06.931583+00:00 [queued]>
[2025-01-30T11:58:09.719+0000] {taskinstance.py:2613} INFO - Dependencies all met for dep_context=requeueable deps ti=<TaskInstance: clean_churn_dataset.extract manual__2025-01-30T11:58:06.931583+00:00 [queued]>
[2025-01-30T11:58:09.720+0000] {taskinstance.py:2866} INFO - Starting attempt 1 of 1
[2025-01-30T11:58:09.732+0000] {taskinstance.py:2889} INFO - Executing <Task(_PythonDecoratedOperator): extract> on 2025-01-30 11:58:06.931583+00:00
[2025-01-30T11:58:09.741+0000] {standard_task_runner.py:72} INFO - Started process 99 to run task
[2025-01-30T11:58:09.747+0000] {standard_task_runner.py:104} INFO - Running: ['***', 'tasks', 'run', 'clean_churn_dataset', 'extract', 'manual__2025-01-30T11:58:06.931583+00:00', '--job-id', '99', '--raw', '--subdir', 'DAGS_FOLDER/clean_churn.py', '--cfg-path', '/tmp/tmp6ejta8vx']
[2025-01-30T11:58:09.750+0000] {standard_task_runner.py:105} INFO - Job 99: Subtask extract
[2025-01-30T11:58:09.857+0000] {task_command.py:467} INFO - Running <TaskInstance: clean_churn_dataset.extract manual__2025-01-30T11:58:06.931583+00:00 [running]> on host e8c2e07890ed
[2025-01-30T11:58:09.957+0000] {taskinstance.py:3132} INFO - Exporting env vars: AIRFLOW_CTX_DAG_OWNER='***' AIRFLOW_CTX_DAG_ID='clean_churn_dataset' AIRFLOW_CTX_TASK_ID='extract' AIRFLOW_CTX_EXECUTION_DATE='2025-01-30T11:58:06.931583+00:00' AIRFLOW_CTX_TRY_NUMBER='1' AIRFLOW_CTX_DAG_RUN_ID='manual__2025-01-30T11:58:06.931583+00:00'
[2025-01-30T11:58:09.961+0000] {logging_mixin.py:190} INFO - Task instance is in running state
[2025-01-30T11:58:09.962+0000] {logging_mixin.py:190} INFO -  Previous state of the Task instance: queued
[2025-01-30T11:58:09.963+0000] {logging_mixin.py:190} INFO - Current task name:extract state:running start_date:2025-01-30 11:58:09.710344+00:00
[2025-01-30T11:58:09.963+0000] {logging_mixin.py:190} INFO - Dag name:clean_churn_dataset and current dag run status:running
[2025-01-30T11:58:09.964+0000] {taskinstance.py:731} INFO - ::endgroup::
[2025-01-30T11:58:09.966+0000] {clean_churn.py:66} INFO - Извлечение данных из таблицы users_churn.
[2025-01-30T11:58:09.983+0000] {base.py:84} INFO - Retrieving connection 'source_db'
[2025-01-30T11:58:09.985+0000] {sql.py:186} WARNING - This setter is for backward compatibility and should not be used.
Since the introduction of connection property, the providers listed below breaks due to assigning value to self.connection in their __init__ method.
* apache-***-providers-mysql<5.7.1
* apache-***-providers-elasticsearch<5.5.1
* apache-***-providers-postgres<5.13.0
[2025-01-30T11:58:10.179+0000] {warnings.py:109} WARNING - /opt/***/dags/clean_churn.py:78: UserWarning: pandas only supports SQLAlchemy connectable (engine/connection) or database string URI or sqlite3 DBAPI2 connection. Other DBAPI2 objects are not tested. Please consider using SQLAlchemy.
  data = pd.read_sql(sql, conn)

[2025-01-30T11:58:10.282+0000] {taskinstance.py:3311} ERROR - Task failed with exception
Traceback (most recent call last):
  File "/home/airflow/.local/lib/python3.10/site-packages/pandas/io/sql.py", line 2018, in execute
    cur.execute(*args, **kwargs)
psycopg2.errors.UndefinedTable: relation "users_churn" does not exist
LINE 8:         FROM users_churn
                     ^


The above exception was the direct cause of the following exception:

Traceback (most recent call last):
  File "/home/airflow/.local/lib/python3.10/site-packages/airflow/models/taskinstance.py", line 767, in _execute_task
    result = _execute_callable(context=context, **execute_callable_kwargs)
  File "/home/airflow/.local/lib/python3.10/site-packages/airflow/models/taskinstance.py", line 733, in _execute_callable
    return ExecutionCallableRunner(
  File "/home/airflow/.local/lib/python3.10/site-packages/airflow/utils/operator_helpers.py", line 252, in run
    return self.func(*args, **kwargs)
  File "/home/airflow/.local/lib/python3.10/site-packages/airflow/models/baseoperator.py", line 422, in wrapper
    return func(self, *args, **kwargs)
  File "/home/airflow/.local/lib/python3.10/site-packages/airflow/decorators/base.py", line 266, in execute
    return_value = super().execute(context)
  File "/home/airflow/.local/lib/python3.10/site-packages/airflow/models/baseoperator.py", line 422, in wrapper
    return func(self, *args, **kwargs)
  File "/home/airflow/.local/lib/python3.10/site-packages/airflow/operators/python.py", line 238, in execute
    return_value = self.execute_callable()
  File "/home/airflow/.local/lib/python3.10/site-packages/airflow/operators/python.py", line 256, in execute_callable
    return runner.run(*self.op_args, **self.op_kwargs)
  File "/home/airflow/.local/lib/python3.10/site-packages/airflow/utils/operator_helpers.py", line 252, in run
    return self.func(*args, **kwargs)
  File "/opt/airflow/dags/clean_churn.py", line 78, in extract
    data = pd.read_sql(sql, conn)
  File "/home/airflow/.local/lib/python3.10/site-packages/pandas/io/sql.py", line 564, in read_sql
    return pandas_sql.read_query(
  File "/home/airflow/.local/lib/python3.10/site-packages/pandas/io/sql.py", line 2078, in read_query
    cursor = self.execute(*args)
  File "/home/airflow/.local/lib/python3.10/site-packages/pandas/io/sql.py", line 2030, in execute
    raise ex from exc
pandas.errors.DatabaseError: Execution failed on sql '
        SELECT
            customer_id, begin_date, end_date, type, paperless_billing, payment_method,
            monthly_charges, total_charges, internet_service, online_security,
            online_backup, device_protection, tech_support, streaming_tv,
            streaming_movies, gender, senior_citizen, partner,
            dependents, multiple_lines
        FROM users_churn
        ': relation "users_churn" does not exist
LINE 8:         FROM users_churn
                     ^

[2025-01-30T11:58:10.304+0000] {logging_mixin.py:190} INFO - Task instance in failure state
[2025-01-30T11:58:10.305+0000] {logging_mixin.py:190} INFO - Task start:2025-01-30 11:58:09.710344+00:00 end:2025-01-30 11:58:10.303342+00:00 duration:0.592998
[2025-01-30T11:58:10.306+0000] {logging_mixin.py:190} INFO - Task:<Task(_PythonDecoratedOperator): extract> dag:<DAG: clean_churn_dataset> dagrun:<DagRun clean_churn_dataset @ 2025-01-30 11:58:06.931583+00:00: manual__2025-01-30T11:58:06.931583+00:00, state:running, queued_at: 2025-01-30 11:58:06.953114+00:00. externally triggered: True>
[2025-01-30T11:58:10.306+0000] {logging_mixin.py:190} INFO - Failure caused by Execution failed on sql '
        SELECT
            customer_id, begin_date, end_date, type, paperless_billing, payment_method,
            monthly_charges, total_charges, internet_service, online_security,
            online_backup, device_protection, tech_support, streaming_tv,
            streaming_movies, gender, senior_citizen, partner,
            dependents, multiple_lines
        FROM users_churn
        ': relation "users_churn" does not exist
LINE 8:         FROM users_churn
                     ^
[2025-01-30T11:58:10.307+0000] {taskinstance.py:1225} INFO - Marking task as FAILED. dag_id=clean_churn_dataset, task_id=extract, run_id=manual__2025-01-30T11:58:06.931583+00:00, execution_date=20250130T115806, start_date=20250130T115809, end_date=20250130T115810
[2025-01-30T11:58:10.320+0000] {taskinstance.py:340} INFO - ::group::Post task execution logs
[2025-01-30T11:58:10.321+0000] {standard_task_runner.py:124} ERROR - Failed to execute job 99 for task extract (Execution failed on sql '
        SELECT
            customer_id, begin_date, end_date, type, paperless_billing, payment_method,
            monthly_charges, total_charges, internet_service, online_security,
            online_backup, device_protection, tech_support, streaming_tv,
            streaming_movies, gender, senior_citizen, partner,
            dependents, multiple_lines
        FROM users_churn
        ': relation "users_churn" does not exist
LINE 8:         FROM users_churn
                     ^
; 99)
Traceback (most recent call last):
  File "/home/airflow/.local/lib/python3.10/site-packages/pandas/io/sql.py", line 2018, in execute
    cur.execute(*args, **kwargs)
psycopg2.errors.UndefinedTable: relation "users_churn" does not exist
LINE 8:         FROM users_churn
                     ^


The above exception was the direct cause of the following exception:

Traceback (most recent call last):
  File "/home/airflow/.local/lib/python3.10/site-packages/airflow/task/task_runner/standard_task_runner.py", line 117, in _start_by_fork
    ret = args.func(args, dag=self.dag)
  File "/home/airflow/.local/lib/python3.10/site-packages/airflow/cli/cli_config.py", line 49, in command
    return func(*args, **kwargs)
  File "/home/airflow/.local/lib/python3.10/site-packages/airflow/utils/cli.py", line 116, in wrapper
    return f(*args, **kwargs)
  File "/home/airflow/.local/lib/python3.10/site-packages/airflow/cli/commands/task_command.py", line 483, in task_run
    task_return_code = _run_task_by_selected_method(args, _dag, ti)
  File "/home/airflow/.local/lib/python3.10/site-packages/airflow/cli/commands/task_command.py", line 256, in _run_task_by_selected_method
    return _run_raw_task(args, ti)
  File "/home/airflow/.local/lib/python3.10/site-packages/airflow/cli/commands/task_command.py", line 341, in _run_raw_task
    return ti._run_raw_task(
  File "/home/airflow/.local/lib/python3.10/site-packages/airflow/utils/session.py", line 97, in wrapper
    return func(*args, session=session, **kwargs)
  File "/home/airflow/.local/lib/python3.10/site-packages/airflow/models/taskinstance.py", line 3005, in _run_raw_task
    return _run_raw_task(
  File "/home/airflow/.local/lib/python3.10/site-packages/airflow/models/taskinstance.py", line 273, in _run_raw_task
    TaskInstance._execute_task_with_callbacks(
  File "/home/airflow/.local/lib/python3.10/site-packages/airflow/models/taskinstance.py", line 3159, in _execute_task_with_callbacks
    result = self._execute_task(context, task_orig)
  File "/home/airflow/.local/lib/python3.10/site-packages/airflow/models/taskinstance.py", line 3183, in _execute_task
    return _execute_task(self, context, task_orig)
  File "/home/airflow/.local/lib/python3.10/site-packages/airflow/models/taskinstance.py", line 767, in _execute_task
    result = _execute_callable(context=context, **execute_callable_kwargs)
  File "/home/airflow/.local/lib/python3.10/site-packages/airflow/models/taskinstance.py", line 733, in _execute_callable
    return ExecutionCallableRunner(
  File "/home/airflow/.local/lib/python3.10/site-packages/airflow/utils/operator_helpers.py", line 252, in run
    return self.func(*args, **kwargs)
  File "/home/airflow/.local/lib/python3.10/site-packages/airflow/models/baseoperator.py", line 422, in wrapper
    return func(self, *args, **kwargs)
  File "/home/airflow/.local/lib/python3.10/site-packages/airflow/decorators/base.py", line 266, in execute
    return_value = super().execute(context)
  File "/home/airflow/.local/lib/python3.10/site-packages/airflow/models/baseoperator.py", line 422, in wrapper
    return func(self, *args, **kwargs)
  File "/home/airflow/.local/lib/python3.10/site-packages/airflow/operators/python.py", line 238, in execute
    return_value = self.execute_callable()
  File "/home/airflow/.local/lib/python3.10/site-packages/airflow/operators/python.py", line 256, in execute_callable
    return runner.run(*self.op_args, **self.op_kwargs)
  File "/home/airflow/.local/lib/python3.10/site-packages/airflow/utils/operator_helpers.py", line 252, in run
    return self.func(*args, **kwargs)
  File "/opt/airflow/dags/clean_churn.py", line 78, in extract
    data = pd.read_sql(sql, conn)
  File "/home/airflow/.local/lib/python3.10/site-packages/pandas/io/sql.py", line 564, in read_sql
    return pandas_sql.read_query(
  File "/home/airflow/.local/lib/python3.10/site-packages/pandas/io/sql.py", line 2078, in read_query
    cursor = self.execute(*args)
  File "/home/airflow/.local/lib/python3.10/site-packages/pandas/io/sql.py", line 2030, in execute
    raise ex from exc
pandas.errors.DatabaseError: Execution failed on sql '
        SELECT
            customer_id, begin_date, end_date, type, paperless_billing, payment_method,
            monthly_charges, total_charges, internet_service, online_security,
            online_backup, device_protection, tech_support, streaming_tv,
            streaming_movies, gender, senior_citizen, partner,
            dependents, multiple_lines
        FROM users_churn
        ': relation "users_churn" does not exist
LINE 8:         FROM users_churn
                     ^

[2025-01-30T11:58:10.378+0000] {local_task_job_runner.py:266} INFO - Task exited with return code 1
[2025-01-30T11:58:10.401+0000] {taskinstance.py:3895} INFO - 0 downstream tasks scheduled from follow-on schedule check
[2025-01-30T11:58:10.405+0000] {local_task_job_runner.py:245} INFO - ::endgroup::
