[2025-01-14T09:53:23.010+0000] {taskinstance.py:1159} INFO - Dependencies all met for dep_context=non-requeueable deps ti=<TaskInstance: prepare_churn_dataset.load manual__2025-01-14T09:53:07.095546+00:00 [queued]>
[2025-01-14T09:53:23.017+0000] {taskinstance.py:1159} INFO - Dependencies all met for dep_context=requeueable deps ti=<TaskInstance: prepare_churn_dataset.load manual__2025-01-14T09:53:07.095546+00:00 [queued]>
[2025-01-14T09:53:23.018+0000] {taskinstance.py:1361} INFO - Starting attempt 1 of 1
[2025-01-14T09:53:23.032+0000] {taskinstance.py:1382} INFO - Executing <Task(_PythonDecoratedOperator): load> on 2025-01-14 09:53:07.095546+00:00
[2025-01-14T09:53:23.039+0000] {standard_task_runner.py:57} INFO - Started process 112 to run task
[2025-01-14T09:53:23.042+0000] {standard_task_runner.py:84} INFO - Running: ['***', 'tasks', 'run', 'prepare_churn_dataset', 'load', 'manual__2025-01-14T09:53:07.095546+00:00', '--job-id', '175', '--raw', '--subdir', 'DAGS_FOLDER/churn.py', '--cfg-path', '/tmp/tmpab23hwab']
[2025-01-14T09:53:23.043+0000] {standard_task_runner.py:85} INFO - Job 175: Subtask load
[2025-01-14T09:53:23.084+0000] {task_command.py:416} INFO - Running <TaskInstance: prepare_churn_dataset.load manual__2025-01-14T09:53:07.095546+00:00 [running]> on host 17ffe0b46e02
[2025-01-14T09:53:23.237+0000] {taskinstance.py:1662} INFO - Exporting env vars: AIRFLOW_CTX_DAG_OWNER='***' AIRFLOW_CTX_DAG_ID='prepare_churn_dataset' AIRFLOW_CTX_TASK_ID='load' AIRFLOW_CTX_EXECUTION_DATE='2025-01-14T09:53:07.095546+00:00' AIRFLOW_CTX_TRY_NUMBER='1' AIRFLOW_CTX_DAG_RUN_ID='manual__2025-01-14T09:53:07.095546+00:00'
[2025-01-14T09:53:23.245+0000] {base.py:73} INFO - Using connection ID 'destination_db' for task execution.
[2025-01-14T09:53:23.500+0000] {taskinstance.py:1937} ERROR - Task failed with exception
Traceback (most recent call last):
  File "/home/airflow/.local/lib/python3.10/site-packages/airflow/decorators/base.py", line 221, in execute
    return_value = super().execute(context)
  File "/home/airflow/.local/lib/python3.10/site-packages/airflow/operators/python.py", line 192, in execute
    return_value = self.execute_callable()
  File "/home/airflow/.local/lib/python3.10/site-packages/airflow/operators/python.py", line 209, in execute_callable
    return self.python_callable(*self.op_args, **self.op_kwargs)
  File "/opt/airflow/dags/churn.py", line 96, in load
    hook.insert_rows(
  File "/home/airflow/.local/lib/python3.10/site-packages/airflow/providers/common/sql/hooks/sql.py", line 509, in insert_rows
    cur.execute(sql, values)
psycopg2.errors.InvalidColumnReference: there is no unique or exclusion constraint matching the ON CONFLICT specification

[2025-01-14T09:53:23.512+0000] {taskinstance.py:1400} INFO - Marking task as FAILED. dag_id=prepare_churn_dataset, task_id=load, execution_date=20250114T095307, start_date=20250114T095323, end_date=20250114T095323
[2025-01-14T09:53:23.525+0000] {standard_task_runner.py:104} ERROR - Failed to execute job 175 for task load (there is no unique or exclusion constraint matching the ON CONFLICT specification
; 112)
[2025-01-14T09:53:23.540+0000] {local_task_job_runner.py:228} INFO - Task exited with return code 1
[2025-01-14T09:53:23.555+0000] {taskinstance.py:2778} INFO - 0 downstream tasks scheduled from follow-on schedule check
