[2025-01-30T06:11:26.143+0000] {local_task_job_runner.py:123} INFO - ::group::Pre task execution logs
[2025-01-30T06:11:26.159+0000] {taskinstance.py:2613} INFO - Dependencies all met for dep_context=non-requeueable deps ti=<TaskInstance: churn.create_table manual__2025-01-30T06:11:24.803224+00:00 [queued]>
[2025-01-30T06:11:26.165+0000] {taskinstance.py:2613} INFO - Dependencies all met for dep_context=requeueable deps ti=<TaskInstance: churn.create_table manual__2025-01-30T06:11:24.803224+00:00 [queued]>
[2025-01-30T06:11:26.166+0000] {taskinstance.py:2866} INFO - Starting attempt 1 of 1
[2025-01-30T06:11:26.177+0000] {taskinstance.py:2889} INFO - Executing <Task(PythonOperator): create_table> on 2025-01-30 06:11:24.803224+00:00
[2025-01-30T06:11:26.184+0000] {standard_task_runner.py:72} INFO - Started process 220 to run task
[2025-01-30T06:11:26.188+0000] {standard_task_runner.py:104} INFO - Running: ['***', 'tasks', 'run', 'churn', 'create_table', 'manual__2025-01-30T06:11:24.803224+00:00', '--job-id', '44', '--raw', '--subdir', 'DAGS_FOLDER/alt_churn.py', '--cfg-path', '/tmp/tmp83zen8vw']
[2025-01-30T06:11:26.189+0000] {standard_task_runner.py:105} INFO - Job 44: Subtask create_table
[2025-01-30T06:11:26.231+0000] {task_command.py:467} INFO - Running <TaskInstance: churn.create_table manual__2025-01-30T06:11:24.803224+00:00 [running]> on host 0be31ceb717f
[2025-01-30T06:11:26.292+0000] {taskinstance.py:3132} INFO - Exporting env vars: AIRFLOW_CTX_DAG_OWNER='***' AIRFLOW_CTX_DAG_ID='churn' AIRFLOW_CTX_TASK_ID='create_table' AIRFLOW_CTX_EXECUTION_DATE='2025-01-30T06:11:24.803224+00:00' AIRFLOW_CTX_TRY_NUMBER='1' AIRFLOW_CTX_DAG_RUN_ID='manual__2025-01-30T06:11:24.803224+00:00'
[2025-01-30T06:11:26.293+0000] {logging_mixin.py:190} INFO - Task instance is in running state
[2025-01-30T06:11:26.294+0000] {logging_mixin.py:190} INFO -  Previous state of the Task instance: queued
[2025-01-30T06:11:26.294+0000] {logging_mixin.py:190} INFO - Current task name:create_table state:running start_date:2025-01-30 06:11:26.159849+00:00
[2025-01-30T06:11:26.295+0000] {logging_mixin.py:190} INFO - Dag name:churn and current dag run status:running
[2025-01-30T06:11:26.295+0000] {taskinstance.py:731} INFO - ::endgroup::
[2025-01-30T06:11:26.303+0000] {base.py:84} INFO - Retrieving connection 'destination_db'
[2025-01-30T06:11:26.304+0000] {sql.py:186} WARNING - This setter is for backward compatibility and should not be used.
Since the introduction of connection property, the providers listed below breaks due to assigning value to self.connection in their __init__ method.
* apache-***-providers-mysql<5.7.1
* apache-***-providers-elasticsearch<5.5.1
* apache-***-providers-postgres<5.13.0
[2025-01-30T06:11:26.310+0000] {base.py:84} INFO - Retrieving connection 'destination_db'
[2025-01-30T06:11:26.748+0000] {churn.py:44} INFO - Создание таблицы alt_users_churn.
[2025-01-30T06:11:26.895+0000] {taskinstance.py:3311} ERROR - Task failed with exception
Traceback (most recent call last):
  File "/home/airflow/.local/lib/python3.10/site-packages/sqlalchemy/engine/base.py", line 1910, in _execute_context
    self.dialect.do_execute(
  File "/home/airflow/.local/lib/python3.10/site-packages/sqlalchemy/engine/default.py", line 736, in do_execute
    cursor.execute(statement, parameters)
psycopg2.errors.DuplicateTable: relation "unique_customer_constraint" already exists


The above exception was the direct cause of the following exception:

Traceback (most recent call last):
  File "/home/airflow/.local/lib/python3.10/site-packages/airflow/models/taskinstance.py", line 767, in _execute_task
    result = _execute_callable(context=context, **execute_callable_kwargs)
  File "/home/airflow/.local/lib/python3.10/site-packages/airflow/models/taskinstance.py", line 733, in _execute_callable
    return ExecutionCallableRunner(
  File "/home/airflow/.local/lib/python3.10/site-packages/airflow/utils/operator_helpers.py", line 252, in run
    return self.func(*args, **kwargs)
  File "/home/airflow/.local/lib/python3.10/site-packages/airflow/models/baseoperator.py", line 422, in wrapper
    return func(self, *args, **kwargs)
  File "/home/airflow/.local/lib/python3.10/site-packages/airflow/operators/python.py", line 238, in execute
    return_value = self.execute_callable()
  File "/home/airflow/.local/lib/python3.10/site-packages/airflow/operators/python.py", line 256, in execute_callable
    return runner.run(*self.op_args, **self.op_kwargs)
  File "/home/airflow/.local/lib/python3.10/site-packages/airflow/utils/operator_helpers.py", line 252, in run
    return self.func(*args, **kwargs)
  File "/opt/airflow/plugins/steps/churn.py", line 45, in create_table
    metadata.create_all(engine)
  File "/home/airflow/.local/lib/python3.10/site-packages/sqlalchemy/sql/schema.py", line 4930, in create_all
    bind._run_ddl_visitor(
  File "/home/airflow/.local/lib/python3.10/site-packages/sqlalchemy/engine/base.py", line 3238, in _run_ddl_visitor
    conn._run_ddl_visitor(visitorcallable, element, **kwargs)
  File "/home/airflow/.local/lib/python3.10/site-packages/sqlalchemy/engine/base.py", line 2221, in _run_ddl_visitor
    visitorcallable(self.dialect, self, **kwargs).traverse_single(element)
  File "/home/airflow/.local/lib/python3.10/site-packages/sqlalchemy/sql/visitors.py", line 524, in traverse_single
    return meth(obj, **kw)
  File "/home/airflow/.local/lib/python3.10/site-packages/sqlalchemy/sql/ddl.py", line 855, in visit_metadata
    self.traverse_single(
  File "/home/airflow/.local/lib/python3.10/site-packages/sqlalchemy/sql/visitors.py", line 524, in traverse_single
    return meth(obj, **kw)
  File "/home/airflow/.local/lib/python3.10/site-packages/sqlalchemy/sql/ddl.py", line 899, in visit_table
    self.connection.execute(
  File "/home/airflow/.local/lib/python3.10/site-packages/sqlalchemy/engine/base.py", line 1385, in execute
    return meth(self, multiparams, params, _EMPTY_EXECUTION_OPTS)
  File "/home/airflow/.local/lib/python3.10/site-packages/sqlalchemy/sql/ddl.py", line 80, in _execute_on_connection
    return connection._execute_ddl(
  File "/home/airflow/.local/lib/python3.10/site-packages/sqlalchemy/engine/base.py", line 1477, in _execute_ddl
    ret = self._execute_context(
  File "/home/airflow/.local/lib/python3.10/site-packages/sqlalchemy/engine/base.py", line 1953, in _execute_context
    self._handle_dbapi_exception(
  File "/home/airflow/.local/lib/python3.10/site-packages/sqlalchemy/engine/base.py", line 2134, in _handle_dbapi_exception
    util.raise_(
  File "/home/airflow/.local/lib/python3.10/site-packages/sqlalchemy/util/compat.py", line 211, in raise_
    raise exception
  File "/home/airflow/.local/lib/python3.10/site-packages/sqlalchemy/engine/base.py", line 1910, in _execute_context
    self.dialect.do_execute(
  File "/home/airflow/.local/lib/python3.10/site-packages/sqlalchemy/engine/default.py", line 736, in do_execute
    cursor.execute(statement, parameters)
sqlalchemy.exc.ProgrammingError: (psycopg2.errors.DuplicateTable) relation "unique_customer_constraint" already exists

[SQL: 
CREATE TABLE alt_users_churn (
	id SERIAL NOT NULL, 
	customer_id VARCHAR NOT NULL, 
	begin_date TIMESTAMP WITHOUT TIME ZONE, 
	end_date TIMESTAMP WITHOUT TIME ZONE, 
	type VARCHAR, 
	paperless_billing VARCHAR, 
	payment_method VARCHAR, 
	monthly_charges FLOAT, 
	total_charges FLOAT, 
	internet_service VARCHAR, 
	online_security VARCHAR, 
	online_backup VARCHAR, 
	device_protection VARCHAR, 
	tech_support VARCHAR, 
	streaming_tv VARCHAR, 
	streaming_movies VARCHAR, 
	gender VARCHAR, 
	senior_citizen INTEGER, 
	partner VARCHAR, 
	dependents VARCHAR, 
	multiple_lines VARCHAR, 
	target INTEGER, 
	PRIMARY KEY (id), 
	CONSTRAINT unique_customer_constraint UNIQUE (customer_id)
)

]
(Background on this error at: https://sqlalche.me/e/14/f405)
[2025-01-30T06:11:26.941+0000] {logging_mixin.py:190} INFO - Task instance in failure state
[2025-01-30T06:11:26.942+0000] {logging_mixin.py:190} INFO - Task start:2025-01-30 06:11:26.159849+00:00 end:2025-01-30 06:11:26.940852+00:00 duration:0.781003
[2025-01-30T06:11:26.942+0000] {logging_mixin.py:190} INFO - Task:<Task(PythonOperator): create_table> dag:<DAG: churn> dagrun:<DagRun churn @ 2025-01-30 06:11:24.803224+00:00: manual__2025-01-30T06:11:24.803224+00:00, state:running, queued_at: 2025-01-30 06:11:24.820970+00:00. externally triggered: True>
[2025-01-30T06:11:26.943+0000] {logging_mixin.py:190} INFO - Failure caused by (psycopg2.errors.DuplicateTable) relation "unique_customer_constraint" already exists

[SQL: 
CREATE TABLE alt_users_churn (
	id SERIAL NOT NULL, 
	customer_id VARCHAR NOT NULL, 
	begin_date TIMESTAMP WITHOUT TIME ZONE, 
	end_date TIMESTAMP WITHOUT TIME ZONE, 
	type VARCHAR, 
	paperless_billing VARCHAR, 
	payment_method VARCHAR, 
	monthly_charges FLOAT, 
	total_charges FLOAT, 
	internet_service VARCHAR, 
	online_security VARCHAR, 
	online_backup VARCHAR, 
	device_protection VARCHAR, 
	tech_support VARCHAR, 
	streaming_tv VARCHAR, 
	streaming_movies VARCHAR, 
	gender VARCHAR, 
	senior_citizen INTEGER, 
	partner VARCHAR, 
	dependents VARCHAR, 
	multiple_lines VARCHAR, 
	target INTEGER, 
	PRIMARY KEY (id), 
	CONSTRAINT unique_customer_constraint UNIQUE (customer_id)
)

]
(Background on this error at: https://sqlalche.me/e/14/f405)
[2025-01-30T06:11:26.944+0000] {taskinstance.py:1225} INFO - Marking task as FAILED. dag_id=churn, task_id=create_table, run_id=manual__2025-01-30T06:11:24.803224+00:00, execution_date=20250130T061124, start_date=20250130T061126, end_date=20250130T061126
[2025-01-30T06:11:26.954+0000] {taskinstance.py:340} INFO - ::group::Post task execution logs
[2025-01-30T06:11:26.955+0000] {standard_task_runner.py:124} ERROR - Failed to execute job 44 for task create_table ((psycopg2.errors.DuplicateTable) relation "unique_customer_constraint" already exists

[SQL: 
CREATE TABLE alt_users_churn (
	id SERIAL NOT NULL, 
	customer_id VARCHAR NOT NULL, 
	begin_date TIMESTAMP WITHOUT TIME ZONE, 
	end_date TIMESTAMP WITHOUT TIME ZONE, 
	type VARCHAR, 
	paperless_billing VARCHAR, 
	payment_method VARCHAR, 
	monthly_charges FLOAT, 
	total_charges FLOAT, 
	internet_service VARCHAR, 
	online_security VARCHAR, 
	online_backup VARCHAR, 
	device_protection VARCHAR, 
	tech_support VARCHAR, 
	streaming_tv VARCHAR, 
	streaming_movies VARCHAR, 
	gender VARCHAR, 
	senior_citizen INTEGER, 
	partner VARCHAR, 
	dependents VARCHAR, 
	multiple_lines VARCHAR, 
	target INTEGER, 
	PRIMARY KEY (id), 
	CONSTRAINT unique_customer_constraint UNIQUE (customer_id)
)

]
(Background on this error at: https://sqlalche.me/e/14/f405); 220)
Traceback (most recent call last):
  File "/home/airflow/.local/lib/python3.10/site-packages/sqlalchemy/engine/base.py", line 1910, in _execute_context
    self.dialect.do_execute(
  File "/home/airflow/.local/lib/python3.10/site-packages/sqlalchemy/engine/default.py", line 736, in do_execute
    cursor.execute(statement, parameters)
psycopg2.errors.DuplicateTable: relation "unique_customer_constraint" already exists


The above exception was the direct cause of the following exception:

Traceback (most recent call last):
  File "/home/airflow/.local/lib/python3.10/site-packages/airflow/task/task_runner/standard_task_runner.py", line 117, in _start_by_fork
    ret = args.func(args, dag=self.dag)
  File "/home/airflow/.local/lib/python3.10/site-packages/airflow/cli/cli_config.py", line 49, in command
    return func(*args, **kwargs)
  File "/home/airflow/.local/lib/python3.10/site-packages/airflow/utils/cli.py", line 116, in wrapper
    return f(*args, **kwargs)
  File "/home/airflow/.local/lib/python3.10/site-packages/airflow/cli/commands/task_command.py", line 483, in task_run
    task_return_code = _run_task_by_selected_method(args, _dag, ti)
  File "/home/airflow/.local/lib/python3.10/site-packages/airflow/cli/commands/task_command.py", line 256, in _run_task_by_selected_method
    return _run_raw_task(args, ti)
  File "/home/airflow/.local/lib/python3.10/site-packages/airflow/cli/commands/task_command.py", line 341, in _run_raw_task
    return ti._run_raw_task(
  File "/home/airflow/.local/lib/python3.10/site-packages/airflow/utils/session.py", line 97, in wrapper
    return func(*args, session=session, **kwargs)
  File "/home/airflow/.local/lib/python3.10/site-packages/airflow/models/taskinstance.py", line 3005, in _run_raw_task
    return _run_raw_task(
  File "/home/airflow/.local/lib/python3.10/site-packages/airflow/models/taskinstance.py", line 273, in _run_raw_task
    TaskInstance._execute_task_with_callbacks(
  File "/home/airflow/.local/lib/python3.10/site-packages/airflow/models/taskinstance.py", line 3159, in _execute_task_with_callbacks
    result = self._execute_task(context, task_orig)
  File "/home/airflow/.local/lib/python3.10/site-packages/airflow/models/taskinstance.py", line 3183, in _execute_task
    return _execute_task(self, context, task_orig)
  File "/home/airflow/.local/lib/python3.10/site-packages/airflow/models/taskinstance.py", line 767, in _execute_task
    result = _execute_callable(context=context, **execute_callable_kwargs)
  File "/home/airflow/.local/lib/python3.10/site-packages/airflow/models/taskinstance.py", line 733, in _execute_callable
    return ExecutionCallableRunner(
  File "/home/airflow/.local/lib/python3.10/site-packages/airflow/utils/operator_helpers.py", line 252, in run
    return self.func(*args, **kwargs)
  File "/home/airflow/.local/lib/python3.10/site-packages/airflow/models/baseoperator.py", line 422, in wrapper
    return func(self, *args, **kwargs)
  File "/home/airflow/.local/lib/python3.10/site-packages/airflow/operators/python.py", line 238, in execute
    return_value = self.execute_callable()
  File "/home/airflow/.local/lib/python3.10/site-packages/airflow/operators/python.py", line 256, in execute_callable
    return runner.run(*self.op_args, **self.op_kwargs)
  File "/home/airflow/.local/lib/python3.10/site-packages/airflow/utils/operator_helpers.py", line 252, in run
    return self.func(*args, **kwargs)
  File "/opt/airflow/plugins/steps/churn.py", line 45, in create_table
    metadata.create_all(engine)
  File "/home/airflow/.local/lib/python3.10/site-packages/sqlalchemy/sql/schema.py", line 4930, in create_all
    bind._run_ddl_visitor(
  File "/home/airflow/.local/lib/python3.10/site-packages/sqlalchemy/engine/base.py", line 3238, in _run_ddl_visitor
    conn._run_ddl_visitor(visitorcallable, element, **kwargs)
  File "/home/airflow/.local/lib/python3.10/site-packages/sqlalchemy/engine/base.py", line 2221, in _run_ddl_visitor
    visitorcallable(self.dialect, self, **kwargs).traverse_single(element)
  File "/home/airflow/.local/lib/python3.10/site-packages/sqlalchemy/sql/visitors.py", line 524, in traverse_single
    return meth(obj, **kw)
  File "/home/airflow/.local/lib/python3.10/site-packages/sqlalchemy/sql/ddl.py", line 855, in visit_metadata
    self.traverse_single(
  File "/home/airflow/.local/lib/python3.10/site-packages/sqlalchemy/sql/visitors.py", line 524, in traverse_single
    return meth(obj, **kw)
  File "/home/airflow/.local/lib/python3.10/site-packages/sqlalchemy/sql/ddl.py", line 899, in visit_table
    self.connection.execute(
  File "/home/airflow/.local/lib/python3.10/site-packages/sqlalchemy/engine/base.py", line 1385, in execute
    return meth(self, multiparams, params, _EMPTY_EXECUTION_OPTS)
  File "/home/airflow/.local/lib/python3.10/site-packages/sqlalchemy/sql/ddl.py", line 80, in _execute_on_connection
    return connection._execute_ddl(
  File "/home/airflow/.local/lib/python3.10/site-packages/sqlalchemy/engine/base.py", line 1477, in _execute_ddl
    ret = self._execute_context(
  File "/home/airflow/.local/lib/python3.10/site-packages/sqlalchemy/engine/base.py", line 1953, in _execute_context
    self._handle_dbapi_exception(
  File "/home/airflow/.local/lib/python3.10/site-packages/sqlalchemy/engine/base.py", line 2134, in _handle_dbapi_exception
    util.raise_(
  File "/home/airflow/.local/lib/python3.10/site-packages/sqlalchemy/util/compat.py", line 211, in raise_
    raise exception
  File "/home/airflow/.local/lib/python3.10/site-packages/sqlalchemy/engine/base.py", line 1910, in _execute_context
    self.dialect.do_execute(
  File "/home/airflow/.local/lib/python3.10/site-packages/sqlalchemy/engine/default.py", line 736, in do_execute
    cursor.execute(statement, parameters)
sqlalchemy.exc.ProgrammingError: (psycopg2.errors.DuplicateTable) relation "unique_customer_constraint" already exists

[SQL: 
CREATE TABLE alt_users_churn (
	id SERIAL NOT NULL, 
	customer_id VARCHAR NOT NULL, 
	begin_date TIMESTAMP WITHOUT TIME ZONE, 
	end_date TIMESTAMP WITHOUT TIME ZONE, 
	type VARCHAR, 
	paperless_billing VARCHAR, 
	payment_method VARCHAR, 
	monthly_charges FLOAT, 
	total_charges FLOAT, 
	internet_service VARCHAR, 
	online_security VARCHAR, 
	online_backup VARCHAR, 
	device_protection VARCHAR, 
	tech_support VARCHAR, 
	streaming_tv VARCHAR, 
	streaming_movies VARCHAR, 
	gender VARCHAR, 
	senior_citizen INTEGER, 
	partner VARCHAR, 
	dependents VARCHAR, 
	multiple_lines VARCHAR, 
	target INTEGER, 
	PRIMARY KEY (id), 
	CONSTRAINT unique_customer_constraint UNIQUE (customer_id)
)

]
(Background on this error at: https://sqlalche.me/e/14/f405)
[2025-01-30T06:11:26.969+0000] {local_task_job_runner.py:266} INFO - Task exited with return code 1
[2025-01-30T06:11:26.993+0000] {taskinstance.py:3895} INFO - 0 downstream tasks scheduled from follow-on schedule check
[2025-01-30T06:11:26.997+0000] {local_task_job_runner.py:245} INFO - ::endgroup::
