[2025-01-10T18:37:18.024+0000] {taskinstance.py:1159} INFO - Dependencies all met for dep_context=non-requeueable deps ti=<TaskInstance: prepare_churn_dataset.load manual__2025-01-10T18:37:04.282172+00:00 [queued]>
[2025-01-10T18:37:18.037+0000] {taskinstance.py:1159} INFO - Dependencies all met for dep_context=requeueable deps ti=<TaskInstance: prepare_churn_dataset.load manual__2025-01-10T18:37:04.282172+00:00 [queued]>
[2025-01-10T18:37:18.037+0000] {taskinstance.py:1361} INFO - Starting attempt 1 of 1
[2025-01-10T18:37:18.058+0000] {taskinstance.py:1382} INFO - Executing <Task(_PythonDecoratedOperator): load> on 2025-01-10 18:37:04.282172+00:00
[2025-01-10T18:37:18.067+0000] {standard_task_runner.py:57} INFO - Started process 106 to run task
[2025-01-10T18:37:18.071+0000] {standard_task_runner.py:84} INFO - Running: ['***', 'tasks', 'run', 'prepare_churn_dataset', 'load', 'manual__2025-01-10T18:37:04.282172+00:00', '--job-id', '87', '--raw', '--subdir', 'DAGS_FOLDER/churn.py', '--cfg-path', '/tmp/tmp83hdngtt']
[2025-01-10T18:37:18.072+0000] {standard_task_runner.py:85} INFO - Job 87: Subtask load
[2025-01-10T18:37:18.131+0000] {task_command.py:416} INFO - Running <TaskInstance: prepare_churn_dataset.load manual__2025-01-10T18:37:04.282172+00:00 [running]> on host 14239e7efa29
[2025-01-10T18:37:18.367+0000] {taskinstance.py:1662} INFO - Exporting env vars: AIRFLOW_CTX_DAG_OWNER='***' AIRFLOW_CTX_DAG_ID='prepare_churn_dataset' AIRFLOW_CTX_TASK_ID='load' AIRFLOW_CTX_EXECUTION_DATE='2025-01-10T18:37:04.282172+00:00' AIRFLOW_CTX_TRY_NUMBER='1' AIRFLOW_CTX_DAG_RUN_ID='manual__2025-01-10T18:37:04.282172+00:00'
[2025-01-10T18:37:18.379+0000] {base.py:73} INFO - Using connection ID 'destination_db' for task execution.
[2025-01-10T18:37:18.620+0000] {taskinstance.py:1937} ERROR - Task failed with exception
Traceback (most recent call last):
  File "/home/airflow/.local/lib/python3.10/site-packages/airflow/decorators/base.py", line 221, in execute
    return_value = super().execute(context)
  File "/home/airflow/.local/lib/python3.10/site-packages/airflow/operators/python.py", line 192, in execute
    return_value = self.execute_callable()
  File "/home/airflow/.local/lib/python3.10/site-packages/airflow/operators/python.py", line 209, in execute_callable
    return self.python_callable(*self.op_args, **self.op_kwargs)
  File "/opt/airflow/dags/churn.py", line 96, in load
    hook.insert_rows(
  File "/home/airflow/.local/lib/python3.10/site-packages/airflow/providers/common/sql/hooks/sql.py", line 509, in insert_rows
    cur.execute(sql, values)
psycopg2.errors.InvalidColumnReference: there is no unique or exclusion constraint matching the ON CONFLICT specification

[2025-01-10T18:37:18.631+0000] {taskinstance.py:1400} INFO - Marking task as FAILED. dag_id=prepare_churn_dataset, task_id=load, execution_date=20250110T183704, start_date=20250110T183718, end_date=20250110T183718
[2025-01-10T18:37:18.644+0000] {standard_task_runner.py:104} ERROR - Failed to execute job 87 for task load (there is no unique or exclusion constraint matching the ON CONFLICT specification
; 106)
[2025-01-10T18:37:18.685+0000] {local_task_job_runner.py:228} INFO - Task exited with return code 1
[2025-01-10T18:37:18.701+0000] {taskinstance.py:2778} INFO - 0 downstream tasks scheduled from follow-on schedule check
