[2025-01-10T15:20:16.858+0000] {taskinstance.py:1159} INFO - Dependencies all met for dep_context=non-requeueable deps ti=<TaskInstance: prepare_churn_dataset.load manual__2025-01-10T15:20:10.308988+00:00 [queued]>
[2025-01-10T15:20:16.864+0000] {taskinstance.py:1159} INFO - Dependencies all met for dep_context=requeueable deps ti=<TaskInstance: prepare_churn_dataset.load manual__2025-01-10T15:20:10.308988+00:00 [queued]>
[2025-01-10T15:20:16.865+0000] {taskinstance.py:1361} INFO - Starting attempt 1 of 1
[2025-01-10T15:20:16.877+0000] {taskinstance.py:1382} INFO - Executing <Task(_PythonDecoratedOperator): load> on 2025-01-10 15:20:10.308988+00:00
[2025-01-10T15:20:16.884+0000] {standard_task_runner.py:57} INFO - Started process 768 to run task
[2025-01-10T15:20:16.886+0000] {standard_task_runner.py:84} INFO - Running: ['***', 'tasks', 'run', 'prepare_churn_dataset', 'load', 'manual__2025-01-10T15:20:10.308988+00:00', '--job-id', '44', '--raw', '--subdir', 'DAGS_FOLDER/churn.py', '--cfg-path', '/tmp/tmp2szw745z']
[2025-01-10T15:20:16.887+0000] {standard_task_runner.py:85} INFO - Job 44: Subtask load
[2025-01-10T15:20:16.925+0000] {task_command.py:416} INFO - Running <TaskInstance: prepare_churn_dataset.load manual__2025-01-10T15:20:10.308988+00:00 [running]> on host 6c2c8705fe78
[2025-01-10T15:20:17.066+0000] {taskinstance.py:1662} INFO - Exporting env vars: AIRFLOW_CTX_DAG_OWNER='***' AIRFLOW_CTX_DAG_ID='prepare_churn_dataset' AIRFLOW_CTX_TASK_ID='load' AIRFLOW_CTX_EXECUTION_DATE='2025-01-10T15:20:10.308988+00:00' AIRFLOW_CTX_TRY_NUMBER='1' AIRFLOW_CTX_DAG_RUN_ID='manual__2025-01-10T15:20:10.308988+00:00'
[2025-01-10T15:20:17.074+0000] {base.py:73} INFO - Using connection ID 'destination_db' for task execution.
[2025-01-10T15:20:17.265+0000] {taskinstance.py:1937} ERROR - Task failed with exception
Traceback (most recent call last):
  File "/home/airflow/.local/lib/python3.10/site-packages/airflow/decorators/base.py", line 221, in execute
    return_value = super().execute(context)
  File "/home/airflow/.local/lib/python3.10/site-packages/airflow/operators/python.py", line 192, in execute
    return_value = self.execute_callable()
  File "/home/airflow/.local/lib/python3.10/site-packages/airflow/operators/python.py", line 209, in execute_callable
    return self.python_callable(*self.op_args, **self.op_kwargs)
  File "/opt/airflow/dags/churn.py", line 97, in load
    hook.insert_rows(
  File "/home/airflow/.local/lib/python3.10/site-packages/airflow/providers/common/sql/hooks/sql.py", line 509, in insert_rows
    cur.execute(sql, values)
psycopg2.errors.InvalidColumnReference: there is no unique or exclusion constraint matching the ON CONFLICT specification

[2025-01-10T15:20:17.276+0000] {taskinstance.py:1400} INFO - Marking task as FAILED. dag_id=prepare_churn_dataset, task_id=load, execution_date=20250110T152010, start_date=20250110T152016, end_date=20250110T152017
[2025-01-10T15:20:17.286+0000] {standard_task_runner.py:104} ERROR - Failed to execute job 44 for task load (there is no unique or exclusion constraint matching the ON CONFLICT specification
; 768)
[2025-01-10T15:20:17.302+0000] {local_task_job_runner.py:228} INFO - Task exited with return code 1
[2025-01-10T15:20:17.319+0000] {taskinstance.py:2778} INFO - 0 downstream tasks scheduled from follow-on schedule check
