[2025-01-10T18:28:06.773+0000] {taskinstance.py:1159} INFO - Dependencies all met for dep_context=non-requeueable deps ti=<TaskInstance: prepare_churn_dataset.load manual__2025-01-10T18:27:57.080629+00:00 [queued]>
[2025-01-10T18:28:06.781+0000] {taskinstance.py:1159} INFO - Dependencies all met for dep_context=requeueable deps ti=<TaskInstance: prepare_churn_dataset.load manual__2025-01-10T18:27:57.080629+00:00 [queued]>
[2025-01-10T18:28:06.782+0000] {taskinstance.py:1361} INFO - Starting attempt 1 of 1
[2025-01-10T18:28:06.795+0000] {taskinstance.py:1382} INFO - Executing <Task(_PythonDecoratedOperator): load> on 2025-01-10 18:27:57.080629+00:00
[2025-01-10T18:28:06.802+0000] {standard_task_runner.py:57} INFO - Started process 110 to run task
[2025-01-10T18:28:06.805+0000] {standard_task_runner.py:84} INFO - Running: ['***', 'tasks', 'run', 'prepare_churn_dataset', 'load', 'manual__2025-01-10T18:27:57.080629+00:00', '--job-id', '81', '--raw', '--subdir', 'DAGS_FOLDER/churn.py', '--cfg-path', '/tmp/tmpu09vxpan']
[2025-01-10T18:28:06.806+0000] {standard_task_runner.py:85} INFO - Job 81: Subtask load
[2025-01-10T18:28:06.861+0000] {task_command.py:416} INFO - Running <TaskInstance: prepare_churn_dataset.load manual__2025-01-10T18:27:57.080629+00:00 [running]> on host a5f039dbec13
[2025-01-10T18:28:07.036+0000] {taskinstance.py:1662} INFO - Exporting env vars: AIRFLOW_CTX_DAG_OWNER='***' AIRFLOW_CTX_DAG_ID='prepare_churn_dataset' AIRFLOW_CTX_TASK_ID='load' AIRFLOW_CTX_EXECUTION_DATE='2025-01-10T18:27:57.080629+00:00' AIRFLOW_CTX_TRY_NUMBER='1' AIRFLOW_CTX_DAG_RUN_ID='manual__2025-01-10T18:27:57.080629+00:00'
[2025-01-10T18:28:07.046+0000] {base.py:73} INFO - Using connection ID 'destination_db' for task execution.
[2025-01-10T18:28:07.243+0000] {taskinstance.py:1937} ERROR - Task failed with exception
Traceback (most recent call last):
  File "/home/airflow/.local/lib/python3.10/site-packages/airflow/decorators/base.py", line 221, in execute
    return_value = super().execute(context)
  File "/home/airflow/.local/lib/python3.10/site-packages/airflow/operators/python.py", line 192, in execute
    return_value = self.execute_callable()
  File "/home/airflow/.local/lib/python3.10/site-packages/airflow/operators/python.py", line 209, in execute_callable
    return self.python_callable(*self.op_args, **self.op_kwargs)
  File "/opt/airflow/dags/churn.py", line 97, in load
    hook.insert_rows(
  File "/home/airflow/.local/lib/python3.10/site-packages/airflow/providers/common/sql/hooks/sql.py", line 509, in insert_rows
    cur.execute(sql, values)
psycopg2.errors.InvalidColumnReference: there is no unique or exclusion constraint matching the ON CONFLICT specification

[2025-01-10T18:28:07.254+0000] {taskinstance.py:1400} INFO - Marking task as FAILED. dag_id=prepare_churn_dataset, task_id=load, execution_date=20250110T182757, start_date=20250110T182806, end_date=20250110T182807
[2025-01-10T18:28:07.267+0000] {standard_task_runner.py:104} ERROR - Failed to execute job 81 for task load (there is no unique or exclusion constraint matching the ON CONFLICT specification
; 110)
[2025-01-10T18:28:07.298+0000] {local_task_job_runner.py:228} INFO - Task exited with return code 1
[2025-01-10T18:28:07.312+0000] {taskinstance.py:2778} INFO - 0 downstream tasks scheduled from follow-on schedule check
